<?xml version="1.0" encoding="utf-8"?>
<sdf version='1.11'>
  <model name='butterfly' canonical_link = 'base_footprint'>

    <frame name="lidar_frame" attached_to='base_footprint'>
          <pose>0 0 0 0 0 -1.57</pose>
    </frame>

    <frame name="camera_frame" attached_to='base_footprint'>
          <pose>0 0 -1 0 0 -1.57</pose>
    </frame>

    <link name='base_footprint'>
      <inertial>
          <mass>0.513</mass>
          <pose>0 0 0.05 0 0 0</pose> 
        <inertia>
            <ixx>1.0</ixx>
            <iyy>1.0</iyy>
            <izz>1.0</izz>
            <ixy>0.0</ixy>
            <ixz>0.0</ixz>
            <iyz>0.0</iyz>
        </inertia>
      </inertial>
      <collision name='base_footprint_fixed_joint_lump__base_link_collision'>
        <pose>0 0 0.001 0 0 0</pose>
        <geometry>
          <mesh>
            <scale>1 1 1</scale>
            <uri>model://meshes/visual/base_link.STL</uri>
          </mesh>
        </geometry>
      </collision>
      <visual name='base_footprint_visual'>
        <pose>0 0 0 0 0 0</pose>
        <geometry>
          <box>
            <size>0.001 0.001 0.001</size>
          </box>
        </geometry>
      </visual>
      <visual name='base_footprint_fixed_joint_lump__base_link_visual_1'>
        <pose>0 0 0.001 0 0 0</pose>
        <geometry>
          <mesh>
            <scale>1 1 1</scale>
            <uri>model://meshes/visual/base_link.STL</uri>
          </mesh>
        </geometry>
        <material>
          <diffuse>0.941176474 0.166652918 0.69416666 1</diffuse>
          <ambient>0.941176474 0.166652918 0.69416666 1</ambient>
        </material>
      </visual>

      <sensor name='gpu_lidar' type='gpu_lidar'>
          <pose relative_to='lidar_frame'>0 0 0 0 0 0</pose>
          <topic>lidar_scan</topic>
          <update_rate>10</update_rate>
          <ray>
              <scan>
                  <horizontal>
                      <samples>640</samples>
                      <resolution>1</resolution>
                      <min_angle>-1.396263</min_angle>
                      <max_angle>1.396263</max_angle>
                  </horizontal>
                  <vertical>
                      <samples>1</samples>
                      <resolution>0.01</resolution>
                      <min_angle>0</min_angle>
                      <max_angle>0</max_angle>
                  </vertical>
              </scan>
              <range>
                  <min>0.08</min>
                  <max>10.0</max>
                  <resolution>0.01</resolution>
              </range>
          </ray>
          <always_on>1</always_on>
          <visualize>true</visualize>
      </sensor>
      <sensor name="boundingbox_camera" type="boundingbox_camera">
         <pose relative_to='camera_frame'>0 0 0 0 0 0</pose>
         <topic>boxes</topic>
         <camera>
           <box_type>2d</box_type>
           <horizontal_fov>1.047</horizontal_fov>
           <image>
             <width>800</width>
             <height>600</height>
           </image>
           <clip>
             <near>0.1</near>
             <far>10</far>
           </clip>
         </camera>
         <always_on>1</always_on>
         <update_rate>10</update_rate>
         <visualize>true</visualize>
       </sensor>
       <sensor name="imu_sensor" type="imu">
          <pose>0 0 0 0 0 0</pose>
          <update_rate>100</update_rate>
          <imu>
            <linear_acceleration>
              <x>
                <noise type="gaussian">
                  <mean>0.0</mean>
                  <stddev>0.01</stddev>
                </noise>
              </x>
              <y>
                <noise type="gaussian">
                  <mean>0.0</mean>
                  <stddev>0.01</stddev>
                </noise>
              </y>
              <z>
                <noise type="gaussian">
                  <mean>0.0</mean>
                  <stddev>0.01</stddev>
                </noise>
              </z>
            </linear_acceleration>
            <angular_velocity>
              <x>
                <noise type="gaussian">
                  <mean>0.0</mean>
                  <stddev>0.01</stddev>
                </noise>
              </x>
              <y>
                <noise type="gaussian">
                  <mean>0.0</mean>
                  <stddev>0.01</stddev>
                </noise>
              </y>
              <z>
                <noise type="gaussian">
                  <mean>0.0</mean>
                  <stddev>0.01</stddev>
                </noise>
              </z>
            </angular_velocity>
          </imu>
        </sensor>

    </link>


    <joint name='Left_joint' type='revolute'>
        <pose relative_to='base_footprint'>0.0096273999999999995 -0.018692 -0.00040000000000000002 0 0 -0.17452999999999999</pose>
        <parent>base_footprint</parent>
        <child>Left_Link</child>
        <axis>
          <xyz>0 1 0</xyz>
          <limit>
            <lower>-0.34906999999999999</lower>
            <upper>0.34906999999999999</upper>
          </limit>
          <dynamics>
            <spring_reference>0</spring_reference>
            <spring_stiffness>0</spring_stiffness>
          </dynamics>
        </axis>
    </joint>
    <link name='Left_Link'>
        <pose relative_to='Left_joint'>0 0 0 0 0 0</pose>
        <inertial>
          <mass>0.035</mass>
          <pose>0 0 0.05 0 0 0</pose>
          <inertia>
            <ixx>0.1</ixx>
            <iyy>0.1</iyy>
            <izz>0.1</izz>
            <ixy>0.0</ixy>
            <ixz>0.0</ixz>
            <iyz>0.0</iyz>
          </inertia>
        </inertial>
        <collision name='Left_Link_collision'>
          <pose>0 0 0 0 0 0</pose>
          <geometry>
            <mesh>
              <scale>1 1 1</scale>
              <uri>model://meshes/visual/Left_Link.STL</uri>
            </mesh>
          </geometry>
        </collision>
        <visual name='Left_Link_visual'>
          <pose>0 0 0 0 0 0</pose>
          <geometry>
            <mesh>
              <scale>1 1 1</scale>
              <uri>model://meshes/visual/Left_Link.STL</uri>
            </mesh>
          </geometry>
          <material>
            <diffuse>0.949999988 0.637499988 0.275000006 1</diffuse>
            <ambient>0.949999988 0.637499988 0.275000006 1</ambient>
          </material>
        </visual>
    </link>
    <joint name='Right_joint' type='revolute'>
        <pose relative_to='base_footprint'>-0.0096273999999999995 -0.018692 -0.00040000000000000002 0 0 0.17452999999999999</pose>
        <parent>base_footprint</parent>
        <child>Right_Link</child>
        <axis>
          <xyz>0 1 0</xyz>
          <limit>
            <lower>-0.34906999999999999</lower>
            <upper>0.34906999999999999</upper>
            <!-- <effort>0</effort>
            <velocity>0</velocity> -->
          </limit>
          <dynamics>
            <spring_reference>0</spring_reference>
            <spring_stiffness>0</spring_stiffness>
          </dynamics>
        </axis>
    </joint>
    <link name='Right_Link'>
        <pose relative_to='Right_joint'>0 0 0 0 0 0</pose>
        <inertial>
          <mass>0.035</mass>
          <pose>0 0 0.05 0 0 0</pose> <!-- 偏移惯性中心 -->
          <inertia>
            <ixx>0.1</ixx>
            <iyy>0.1</iyy>
            <izz>0.1</izz>
            <ixy>0.0</ixy>
            <ixz>0.0</ixz>
            <iyz>0.0</iyz>
          </inertia>
        </inertial>
        <collision name='Right_Link_collision'>
          <pose>0 0 0 0 0 0</pose>
          <geometry>
            <mesh>
              <scale>1 1 1</scale>
              <uri>model://meshes/visual/Right_Link.STL</uri>
            </mesh>
          </geometry>
        </collision>
        <visual name='Right_Link_visual'>
          <pose>0 0 0 0 0 0</pose>
          <geometry>
            <mesh>
              <scale>1 1 1</scale>
              <uri>model://meshes/visual/Right_Link.STL</uri>
            </mesh>
          </geometry>
          <material>
            <diffuse>0.941174984 0.222214997 0.125 1</diffuse>
            <ambient>0.941174984 0.222214997 0.125 1</ambient>
          </material>
        </visual>
    </link>

    <!-- propellor modules: Links and Joints -->
    <link name='pp_Left'>
      <pose relative_to='Left_Link'>0.05 0.05 0 0 0 0</pose>
      <inertial>
        <pose>0 0 0 0 0 0</pose>
        <mass>0.001</mass> 
        <inertia>
          <ixx>0.0001</ixx>
          <ixy>0</ixy>
          <ixz>0</ixz>
          <iyy>0.0001</iyy>
          <iyz>0</iyz>
          <izz>0.0001</izz>
        </inertia>
      </inertial>
      <collision name='pp_Left_collision'>
        <pose>0.0 0 0 0 0 0</pose>
        <geometry>
          <cylinder>
            <radius>0.05</radius> 
            <length>0.01</length> 
          </cylinder>
        </geometry>
      </collision>
      <visual name='pp_Left_visual'>
        <pose>0.0 0 0 0 0 0</pose>
        <geometry>
          <cylinder>
            <radius>0.05</radius>
            <length>0.01</length>
          </cylinder>
        </geometry>
        <material>
          <diffuse>0.949999988 0.637499988 0.275000006 0.1</diffuse>
          <ambient>0.949999988 0.637499988 0.275000006 0.1</ambient>
        </material>
      </visual>
    </link>
    <joint name='pp_Left_joint' type='revolute'>
      <pose relative_to='Left_Link'> 0.05 0.05 0 0 0 0</pose>
      <parent>base_footprint</parent> 
      <child>pp_Left</child>
        <axis>
          <xyz>0 0 1</xyz>
          <dynamics>
            <damping>0.01</damping>
            <friction>0.01</friction>
          </dynamics>
        </axis>
    </joint>

    <link name='pp_Right'>
      <pose relative_to='Right_Link'>-0.05 0.05 0 0 0 0</pose>
      <inertial>
        <pose>0 0 0 0 0 0</pose>
        <mass>0.001</mass> 
        <inertia>
          <ixx>0.0001</ixx>
          <ixy>0</ixy>
          <ixz>0</ixz>
          <iyy>0.0001</iyy>
          <iyz>0</iyz>
          <izz>0.0001</izz>
        </inertia>
      </inertial>
      <collision name='pp_Right_collision'>
        <pose>0.0 0 0 0 0 0</pose>
        <geometry>
          <cylinder>
            <radius>0.05</radius> 
            <length>0.01</length> 
          </cylinder>
        </geometry>
      </collision>
      <visual name='pp_Right_visual'>
        <pose>0.0 0 0 0 0 0</pose>
        <geometry>
          <cylinder>
            <radius>0.05</radius>
            <length>0.01</length>
          </cylinder>
        </geometry>
        <material>
          <diffuse>0.941174984 0.222214997 0.125 0.1</diffuse>
          <ambient>0.941174984 0.222214997 0.125 0.1</ambient>
        </material>
      </visual>
    </link>
    <joint name='pp_Right_joint' type='revolute'>
      <pose relative_to='Right_Link'> -0.05 0.05 0 0 0 0</pose>
      <parent>base_footprint</parent> 
      <child>pp_Right</child>
        <axis>
          <xyz>0 0 1</xyz>
          <dynamics>
            <damping>0.01</damping>
            <friction>0.01</friction>
          </dynamics>
        </axis>
    </joint>
  
    <plugin
      filename="gz-sim-thruster-system"
      name="gz::sim::systems::Thruster">
      <use_angvel_cmd>0</use_angvel_cmd>
      <joint_name>pp_Left_joint</joint_name> 
      <thrust_coefficient>0.004422</thrust_coefficient>
      <fluid_density>100</fluid_density>
      <propeller_diameter>0.2</propeller_diameter>
    </plugin>

    <plugin
      filename="gz-sim-thruster-system"
      name="gz::sim::systems::Thruster">
      <use_angvel_cmd>0</use_angvel_cmd>
      <joint_name>pp_Right_joint</joint_name> 
      <thrust_coefficient>0.004422</thrust_coefficient>
      <fluid_density>100</fluid_density>
      <propeller_diameter>0.2</propeller_diameter>
    </plugin>

    <plugin
      filename="gz-sim-joint-state-publisher-system"
      name="gz::sim::systems::JointStatePublisher">
      <joint_name>Left_joint</joint_name>
    </plugin>

    <plugin
      filename="gz-sim-joint-state-publisher-system"
      name="gz::sim::systems::JointStatePublisher">
      <joint_name>Right_joint</joint_name>
    </plugin>

    <plugin
      filename="gz-sim-joint-position-controller-system"
      name="gz::sim::systems::JointPositionController">
      <joint_name>pp_Left_joint</joint_name>
      <topic>Left_joint_topic</topic>
      <p_gain>1</p_gain>
      <i_gain>0.1</i_gain>
      <d_gain>0.01</d_gain>
      <i_max>1</i_max>
      <i_min>-1</i_min>
      <cmd_max>1000</cmd_max>
      <cmd_min>-1000</cmd_min>
      <force>0.0</force>
    </plugin>

    <plugin
      filename="gz-sim-joint-position-controller-system"
      name="gz::sim::systems::JointPositionController">
      <joint_name>pp_Right_joint</joint_name>
      <topic>Right_joint_topic</topic>
      <p_gain>1</p_gain>
      <i_gain>0.1</i_gain>
      <d_gain>0.01</d_gain>
      <i_max>1</i_max>
      <i_min>-1</i_min>
      <cmd_max>1000</cmd_max>
      <cmd_min>-1000</cmd_min>
      <force>0.0</force>
    </plugin>

    <pose>0.00010600032654218532 -0.00010600016019757542 0.0 -1.2134942308985258e-07 -8.6638834068117707e-08 2.1183536231089912e-09</pose>
      <static>true</static>
      <self_collide>false</self_collide>
  </model>
</sdf>
